Workbook

Sheet 2026 예산안
A1: 2026 청지기 재정 예산안
A2: 월 수입 3,500,000 · 연간 72,000,000 · 배분율 78.8%
A4: ── 층별 요약 ──
B5: 1층 하나님의 몫 | C5: 650000 | D5: 7800000 | G5: 0.10833333 | H5: ████
B6: 2층 사명 프로젝트 | C6: 1110000 | D6: 13320000 | G6: 0.185 | H6: ███████
B7: 3층 청지기 운영 | C7: 2240000 | D7: 26880000 | G7: 0.37333333 | H7: ███████████████
B8: 4층 성장 씨앗 | C8: 20000 | D8: 15240000 | G8: 0.21166667 | H8: ████████
B9: 5층 신뢰 여백 | C9: 710000 | D9: 8520000 | G9: 0.11833333 | H9: █████
B11: 총계 | C11: 4730000 | D11: 56760000 | E11: =E72 | F11: =F72 | G11: 0.78833333
A13: 1층 하나님의 몫 — 먼저 드리고 나머지로 산다
B14: 프로젝트·항목 | C14: 월 예산 | D14: 연 예산 | E14: 실적 | F14: 잔여 | G14: 소진율 | H14: 비고
A15: 십일조 | B15: 십일조 | C15: 350000 | D15: 4200000 | E15: =-SUMIFS('가계부 내역'!$G:$G,'가계부 내역'!$K:$K,B15,'가계부 내역'!$A:$A,">="&DATE(2026,01,01),'가계부 내역'!$A:$A,"<="&DATE(2026,12,31)) | F15: =D15-E15 | G15: =IF(D15=0,"",E15/D15) | H15: =IF(G15="","",REPT("█",MIN(ROUND(G15*20),20)))&" · 월급 10%"
A16: 선교 | B16: 선교 헌금 | C16: 120000 | D16: 1440000 | E16: =-SUMIFS('가계부 내역'!$G:$G,'가계부 내역'!$K:$K,B16,'가계부 내역'!$A:$A,">="&DATE(2026,01,01),'가계부 내역'!$A:$A,"<="&DATE(2026,12,31)) | F16: =D16-E16 | G16: =IF(D16=0,"",E16/D16) | H16: =IF(G16="","",REPT("█",MIN(ROUND(G16*20),20)))&" · 매월 정기"
B17: 해외선교 | C17: 150000 | D17: 1800000 | E17: =-SUMIFS('가계부 내역'!$G:$G,'가계부 내역'!$K:$K,B17,'가계부 내역'!$A:$A,">="&DATE(2026,01,01),'가계부 내역'!$A:$A,"<="&DATE(2026,12,31)) | F17: =D17-E17 | G17: =IF(D17=0,"",E17/D17) | H17: =IF(G17="","",REPT("█",MIN(ROUND(G17*20),20)))&" · 연 1회 단기선교"
B18: 수련회 | C18: 30000 | D18: 360000 | E18: =-SUMIFS('가계부 내역'!$G:$G,'가계부 내역'!$K:$K,B18,'가계부 내역'!$A:$A,">="&DATE(2026,01,01),'가계부 내역'!$A:$A,"<="&DATE(2026,12,31)) | F18: =D18-E18 | G18: =IF(D18=0,"",E18/D18) | H18: =IF(G18="","",REPT("█",MIN(ROUND(G18*20),20)))&" · 연 2회 (겨울+여름)"
B19: ── 선교 소계 ── | C19: =SUM(C16:C18) | D19: =SUM(D16:D18) | E19: =SUM(E16:E18) | F19: =SUM(F16:F18) | G19: =IF(SUM(D16:D18)=0,"",SUM(E16:E18)/SUM(D16:D18))
B20: 하나님의 몫 소계 | C20: =C15+C16+C17+C18 | D20: =D15+D16+D17+D18 | E20: =E15+E16+E17+E18 | F20: =F15+F16+F17+F18 | G20: =IF((D15+D16+D17+D18)=0,"",(E15+E16+E17+E18)/(D15+D16+D17+D18))
A22: 2층 사명 프로젝트 — 하나님이 맡기신 관계와 섬김 — 목표가 예산을 이끈다
B23: 프로젝트·항목 | C23: 월 예산 | D23: 연 예산 | E23: 실적 | F23: 잔여 | G23: 소진율 | H23: 비고
A24: 효도 | B24: 어머니 용돈/적금 | C24: 800000 | D24: 9600000 | E24: =-SUMIFS('가계부 내역'!$G:$G,'가계부 내역'!$K:$K,B24,'가계부 내역'!$A:$A,">="&DATE(2026,01,01),'가계부 내역'!$A:$A,"<="&DATE(2026,12,31)) | F24: =D24-E24 | G24: =IF(D24=0,"",E24/D24) | H24: =IF(G24="","",REPT("█",MIN(ROUND(G24*20),20)))&" · 용돈 50 + 적금 30"
A25: 찬양 | B25: 찬양팀 회비 | C25: 15000 | D25: 180000 | E25: =-SUMIFS('가계부 내역'!$G:$G,'가계부 내역'!$K:$K,B25,'가계부 내역'!$A:$A,">="&DATE(2026,01,01),'가계부 내역'!$A:$A,"<="&DATE(2026,12,31)) | F25: =D25-E25 | G25: =IF(D25=0,"",E25/D25) | H25: =IF(G25="","",REPT("█",MIN(ROUND(G25*20),20)))
A26: 교회/양육 | B26: 식사교제 | C26: 120000 | D26: 1440000 | E26: =-SUMIFS('가계부 내역'!$G:$G,'가계부 내역'!$K:$K,B26,'가계부 내역'!$A:$A,">="&DATE(2026,01,01),'가계부 내역'!$A:$A,"<="&DATE(2026,12,31)) | F26: =D26-E26 | G26: =IF(D26=0,"",E26/D26) | H26: =IF(G26="","",REPT("█",MIN(ROUND(G26*20),20)))&" · 일요일 식사 분리"
A27: ACS | B27: 모임비 | C27: 50000 | D27: 600000 | E27: =-SUMIFS('가계부 내역'!$G:$G,'가계부 내역'!$K:$K,B27,'가계부 내역'!$A:$A,">="&DATE(2026,01,01),'가계부 내역'!$A:$A,"<="&DATE(2026,12,31)) | F27: =D27-E27 | G27: =IF(D27=0,"",E27/D27) | H27: =IF(G27="","",REPT("█",MIN(ROUND(G27*20),20)))&" · 분기 1회, 회당 15만원"
A28: 관계 | B28: 선물 | C28: 40000 | D28: 480000 | E28: =-SUMIFS('가계부 내역'!$G:$G,'가계부 내역'!$K:$K,B28,'가계부 내역'!$A:$A,">="&DATE(2026,01,01),'가계부 내역'!$A:$A,"<="&DATE(2026,12,31)) | F28: =D28-E28 | G28: =IF(D28=0,"",E28/D28) | H28: =IF(G28="","",REPT("█",MIN(ROUND(G28*20),20)))&" · 생일선물 약10명, 건당 5만원"
B29: 동기 계모임 | C29: 15000 | D29: 180000 | E29: =-SUMIFS('가계부 내역'!$G:$G,'가계부 내역'!$K:$K,B29,'가계부 내역'!$A:$A,">="&DATE(2026,01,01),'가계부 내역'!$A:$A,"<="&DATE(2026,12,31)) | F29: =D29-E29 | G29: =IF(D29=0,"",E29/D29) | H29: =IF(G29="","",REPT("█",MIN(ROUND(G29*20),20)))
B30: ── 관계 소계 ── | C30: =SUM(C28:C29) | D30: =SUM(D28:D29) | E30: =SUM(E28:E29) | F30: =SUM(F28:F29) | G30: =IF(SUM(D28:D29)=0,"",SUM(E28:E29)/SUM(D28:D29))
A31: 경조사 | B31: 경조비 | C31: 70000 | D31: 840000 | E31: =-SUMIFS('가계부 내역'!$G:$G,'가계부 내역'!$K:$K,B31,'가계부 내역'!$A:$A,">="&DATE(2026,01,01),'가계부 내역'!$A:$A,"<="&DATE(2026,12,31)) | F31: =D31-E31 | G31: =IF(D31=0,"",E31/D31) | H31: =IF(G31="","",REPT("█",MIN(ROUND(G31*20),20)))&" · 건당 10만원, 연 7~8건"
B32: 사명 프로젝트 소계 | C32: =C24+C25+C26+C27+C28+C29+C31 | D32: =D24+D25+D26+D27+D28+D29+D31 | E32: =E24+E25+E26+E27+E28+E29+E31 | F32: =F24+F25+F26+F27+F28+F29+F31 | G32: =IF((D24+D25+D26+D27+D28+D29+D31)=0,"",(E24+E25+E26+E27+E28+E29+E31)/(D24+D25+D26+D27+D28+D29+D31))
A34: 3층 청지기 운영 — 건강하게 살기 위한 기본 — 절약이 아니라 적정 관리
B35: 프로젝트·항목 | C35: 월 예산 | D35: 연 예산 | E35: 실적 | F35: 잔여 | G35: 소진율 | H35: 비고
A36: 고정비 | B36: 자동차 할부 | C36: 710000 | D36: 8520000 | E36: =-SUMIFS('가계부 내역'!$G:$G,'가계부 내역'!$K:$K,B36,'가계부 내역'!$A:$A,">="&DATE(2026,01,01),'가계부 내역'!$A:$A,"<="&DATE(2026,12,31)) | F36: =D36-E36 | G36: =IF(D36=0,"",E36/D36) | H36: =IF(G36="","",REPT("█",MIN(ROUND(G36*20),20)))&" · 할부금 고정 (실적 700~704K)"
B37: 보험 | C37: 160000 | D37: 1920000 | E37: =-SUMIFS('가계부 내역'!$G:$G,'가계부 내역'!$K:$K,B37,'가계부 내역'!$A:$A,">="&DATE(2026,01,01),'가계부 내역'!$A:$A,"<="&DATE(2026,12,31)) | F37: =D37-E37 | G37: =IF(D37=0,"",E37/D37) | H37: =IF(G37="","",REPT("█",MIN(ROUND(G37*20),20)))&" · 실적 153K"
B38: 통신 | C38: 130000 | D38: 1560000 | E38: =-SUMIFS('가계부 내역'!$G:$G,'가계부 내역'!$K:$K,B38,'가계부 내역'!$A:$A,">="&DATE(2026,01,01),'가계부 내역'!$A:$A,"<="&DATE(2026,12,31)) | F38: =D38-E38 | G38: =IF(D38=0,"",E38/D38) | H38: =IF(G38="","",REPT("█",MIN(ROUND(G38*20),20)))&" · 실적 122K"
B39: 커플통장 | C39: 200000 | D39: 2400000 | E39: =-SUMIFS('가계부 내역'!$G:$G,'가계부 내역'!$K:$K,B39,'가계부 내역'!$A:$A,">="&DATE(2026,01,01),'가계부 내역'!$A:$A,"<="&DATE(2026,12,31)) | F39: =D39-E39 | G39: =IF(D39=0,"",E39/D39) | H39: =IF(G39="","",REPT("█",MIN(ROUND(G39*20),20)))&" · 약정"
B40: AI | C40: 60000 | D40: 720000 | E40: =-SUMIFS('가계부 내역'!$G:$G,'가계부 내역'!$K:$K,B40,'가계부 내역'!$A:$A,">="&DATE(2026,01,01),'가계부 내역'!$A:$A,"<="&DATE(2026,12,31)) | F40: =D40-E40 | G40: =IF(D40=0,"",E40/D40) | H40: =IF(G40="","",REPT("█",MIN(ROUND(G40*20),20)))&" · Claude Pro + ChatGPT Plus (Max 전환 시 재조정)"
B41: ── 고정비 소계 ── | C41: =SUM(C36:C40) | D41: =SUM(D36:D40) | E41: =SUM(E36:E40) | F41: =SUM(F36:F40) | G41: =IF(SUM(D36:D40)=0,"",SUM(E36:E40)/SUM(D36:D40))
A42: 생활비 | B42: 식비 | C42: 500000 | D42: 6000000 | E42: =-SUMIFS('가계부 내역'!$G:$G,'가계부 내역'!$K:$K,B42,'가계부 내역'!$A:$A,">="&DATE(2026,01,01),'가계부 내역'!$A:$A,"<="&DATE(2026,12,31)) | F42: =D42-E42 | G42: =IF(D42=0,"",E42/D42) | H42: =IF(G42="","",REPT("█",MIN(ROUND(G42*20),20)))&" · 일요일 제외, 카페 포함 (실적 약 920K → 500K 절감목표)"
B43: 교통 | C43: 80000 | D43: 960000 | E43: =-SUMIFS('가계부 내역'!$G:$G,'가계부 내역'!$K:$K,B43,'가계부 내역'!$A:$A,">="&DATE(2026,01,01),'가계부 내역'!$A:$A,"<="&DATE(2026,12,31)) | F43: =D43-E43 | G43: =IF(D43=0,"",E43/D43) | H43: =IF(G43="","",REPT("█",MIN(ROUND(G43*20),20)))&" · 실적 77K"
B44: 자동차 유지 | C44: 300000 | D44: 3600000 | E44: =-SUMIFS('가계부 내역'!$G:$G,'가계부 내역'!$K:$K,B44,'가계부 내역'!$A:$A,">="&DATE(2026,01,01),'가계부 내역'!$A:$A,"<="&DATE(2026,12,31)) | F44: =D44-E44 | G44: =IF(D44=0,"",E44/D44) | H44: =IF(G44="","",REPT("█",MIN(ROUND(G44*20),20)))&" · 주유/주차/톨비 (실적 월 250K)"
B45: 생활용품 | C45: 50000 | D45: 600000 | E45: =-SUMIFS('가계부 내역'!$G:$G,'가계부 내역'!$K:$K,B45,'가계부 내역'!$A:$A,">="&DATE(2026,01,01),'가계부 내역'!$A:$A,"<="&DATE(2026,12,31)) | F45: =D45-E45 | G45: =IF(D45=0,"",E45/D45) | H45: =IF(G45="","",REPT("█",MIN(ROUND(G45*20),20)))&" · 쿠팡/다이소/크린토피아 등"
...
