Workbook

Sheet 26.7~27.6 예산안 (신규)
A1: 26.7~27.6 예산안
A2: 월 기본급 | B2: 3500000 | C2: 연간 수입 | D2: 60000000 | E2: 상여금/년 | F2: 17500000
A3: 경과 월수 | B3: =MONTH(NOW())-MONTH(DATE(2026,7,1))+1 | C3: 전월 월급 | D3: =SUMIFS('가계부 내역'!G:G,'가계부 내역'!A:A,">="&EOMONTH(TODAY(),-2)+1,'가계부 내역'!A:A,"<="&EOMONTH(TODAY(),-1),'가계부 내역'!F:F,"급여") | E3: 본월 지출 | F3: =SUMIFS('가계부 내역'!G:G,'가계부 내역'!A:A,">="&EOMONTH(TODAY(),-1)+1,'가계부 내역'!A:A,"<="&EOMONTH(TODAY(),0),'가계부 내역'!C:C,"지출")
A4: 월 소비예산 | B4: =D46 | C4: 연 소비예산 | D4: =E46 | E4: 월 잔여 | F4: =B2-B4 | G4: 연 잔여 | H4: =D2-D4
A6: 구분 | B6: 프로젝트 | C6: 항목 | D6: 월 예산 | E6: 연 예산 | F6: 실적 | G6: 남은 예산 | H6: 여분/부족 | I6: 비고
A7: 고정 | B7: 운영 | C7: 자동차 할부 | D7: 610000 | E7: 7320000 | F7: =SUMIF('가계부 내역'!$K:$K,C7,'가계부 내역'!$G:$G) | G7: =E7+F7 | H7: =D7*$B$3+F7 | I7: 할부금 고정
A8: 고정 | B8: 운영 | C8: 보험 | D8: 160000 | E8: 1920000 | F8: =SUMIF('가계부 내역'!$K:$K,C8,'가계부 내역'!$G:$G) | G8: =E8+F8 | H8: =D8*$B$3+F8 | I8: 실적 153K
A9: 고정 | B9: 운영 | C9: 통신 | D9: 130000 | E9: 1560000 | F9: =SUMIF('가계부 내역'!$K:$K,C9,'가계부 내역'!$G:$G) | G9: =E9+F9 | H9: =D9*$B$3+F9 | I9: 실적 122K
A10: 고정 | B10: 운영 | C10: 커플통장 | D10: 200000 | E10: 2400000 | F10: =SUMIF('가계부 내역'!$K:$K,C10,'가계부 내역'!$G:$G) | G10: =E10+F10 | H10: =D10*$B$3+F10 | I10: 약정
A11: 고정 | B11: 효도 | C11: 어머니 적금 | D11: 300000 | E11: 3600000 | F11: =SUMIF('가계부 내역'!$K:$K,C11,'가계부 내역'!$G:$G) | G11: =E11+F11 | H11: =D11*$B$3+F11 | I11: 약정
A12: 고정 | B12: 운영 | C12: AI | D12: 15000 | E12: 180000 | F12: =SUMIF('가계부 내역'!$K:$K,C12,'가계부 내역'!$G:$G) | G12: =E12+F12 | H12: =D12*$B$3+F12 | I12: 구독
C13: 1층: 고정 지출 소계 | D13: =SUM(D7:D12) | E13: =SUM(E7:E12) | F13: =SUM(F7:F12) | G13: =SUM(G7:G12) | H13: =SUM(H7:H12)
A14: 생활 | B14: 생활 | C14: 식비 | D14: 800000 | E14: 9600000 | F14: =SUMIF('가계부 내역'!$K:$K,C14,'가계부 내역'!$G:$G) | G14: =E14+F14 | H14: =D14*$B$3+F14 | I14: 실적972K→800K 절감목표
A15: 생활 | B15: 생활 | C15: 교통 | D15: 80000 | E15: 960000 | F15: =SUMIF('가계부 내역'!$K:$K,C15,'가계부 내역'!$G:$G) | G15: =E15+F15 | H15: =D15*$B$3+F15 | I15: 실적 77K
A16: 생활 | B16: 생활 | C16: 카페/간식 | D16: 130000 | E16: 1560000 | F16: =SUMIF('가계부 내역'!$K:$K,C16,'가계부 내역'!$G:$G) | G16: =E16+F16 | H16: =D16*$B$3+F16 | I16: 실적 115K
A17: 생활 | B17: 생활 | C17: 자동차 유지 | D17: 200000 | E17: 2400000 | F17: =SUMIF('가계부 내역'!$K:$K,C17,'가계부 내역'!$G:$G) | G17: =E17+F17 | H17: =D17*$B$3+F17 | I17: 주유/톨비/주차 월상
A18: 생활 | B18: 생활 | C18: 생활용품 | D18: 100000 | E18: 1200000 | F18: =SUMIF('가계부 내역'!$K:$K,C18,'가계부 내역'!$G:$G) | G18: =E18+F18 | H18: =D18*$B$3+F18 | I18: 생활잡화
A19: 생활 | B19: 생활 | C19: 온라인쇼핑 | D19: 100000 | E19: 1200000 | F19: =SUMIF('가계부 내역'!$K:$K,C19,'가계부 내역'!$G:$G) | G19: =E19+F19 | H19: =D19*$B$3+F19 | I19: 실적 109K→100K
A20: 생활 | B20: 생활 | C20: 뷰티/미용 | D20: 50000 | E20: 600000 | F20: =SUMIF('가계부 내역'!$K:$K,C20,'가계부 내역'!$G:$G) | G20: =E20+F20 | H20: =D20*$B$3+F20 | I20: 실적 75K→50K
A21: 생활 | B21: 개발 | C21: 도서 | D21: 20000 | E21: 240000 | F21: =SUMIF('가계부 내역'!$K:$K,C21,'가계부 내역'!$G:$G) | G21: =E21+F21 | H21: =D21*$B$3+F21 | I21: 실적 10K
C22: 2층: 생활 지출 소계 | D22: =SUM(D14:D21) | E22: =SUM(E14:E21) | F22: =SUM(F14:F21) | G22: =SUM(G14:G21) | H22: =SUM(H14:H21)
A23: 프로젝트 | B23: 효도 | C23: 어머니 용돈 | D23: 500000 | E23: 6000000 | F23: =SUMIF('가계부 내역'!$K:$K,C23,'가계부 내역'!$G:$G) | G23: =E23+F23 | H23: =D23*$B$3+F23 | I23: 실적 513K
A24: 프로젝트 | B24: 효도 | C24: 어머니 선물 | D24: 150000 | E24: 1800000 | F24: =SUMIF('가계부 내역'!$K:$K,C24,'가계부 내역'!$G:$G) | G24: =E24+F24 | H24: =D24*$B$3+F24 | I24: 월상 소형 선물
A25: 프로젝트 | B25: 선교 | C25: 선교 헌금 | D25: 120000 | E25: 1440000 | F25: =SUMIF('가계부 내역'!$K:$K,C25,'가계부 내역'!$G:$G) | G25: =E25+F25 | H25: =D25*$B$3+F25 | I25: 실적 119K
A26: 프로젝트 | B26: 선교 | C26: 필리핀 | D26: 10000 | E26: 120000 | F26: =SUMIF('가계부 내역'!$K:$K,C26,'가계부 내역'!$G:$G) | G26: =E26+F26 | H26: =D26*$B$3+F26 | I26: 실적 10K
A27: 프로젝트 | B27: 선교 | C27: 수련회 | D27: 15000 | E27: 180000 | F27: =SUMIF('가계부 내역'!$K:$K,C27,'가계부 내역'!$G:$G) | G27: =E27+F27 | H27: =D27*$B$3+F27 | I27: 연 1~2회
A28: 프로젝트 | B28: 찬양 | C28: 찬양팀 회비 | D28: 15000 | E28: 180000 | F28: =SUMIF('가계부 내역'!$K:$K,C28,'가계부 내역'!$G:$G) | G28: =E28+F28 | H28: =D28*$B$3+F28 | I28: 실적 일치
A29: 프로젝트 | B29: 교회/양육 | C29: 식사교제 | D29: 10000 | E29: 120000 | F29: =SUMIF('가계부 내역'!$K:$K,C29,'가계부 내역'!$G:$G) | G29: =E29+F29 | H29: =D29*$B$3+F29 | I29: 실적 7K
A30: 프로젝트 | B30: ACS | C30: 모임비 | D30: 0 | E30: 0 | F30: =SUMIF('가계부 내역'!$K:$K,C30,'가계부 내역'!$G:$G) | G30: =E30+F30 | H30: =D30*$B$3+F30 | I30: 현재 미발생
A31: 프로젝트 | B31: 관계 | C31: 선물 | D31: 100000 | E31: 1200000 | F31: =SUMIF('가계부 내역'!$K:$K,C31,'가계부 내역'!$G:$G) | G31: =E31+F31 | H31: =D31*$B$3+F31 | I31: 월상 소형 선물
A32: 프로젝트 | B32: 관계 | C32: 동기 계모임 | D32: 15000 | E32: 180000 | F32: =SUMIF('가계부 내역'!$K:$K,C32,'가계부 내역'!$G:$G) | G32: =E32+F32 | H32: =D32*$B$3+F32 | I32: 실적 일치
A33: 프로젝트 | B33: 관계 | C33: 파트 회비 | D33: 20000 | E33: 240000 | F33: =SUMIF('가계부 내역'!$K:$K,C33,'가계부 내역'!$G:$G) | G33: =E33+F33 | H33: =D33*$B$3+F33 | I33: 격월 20K
A34: 프로젝트 | B34: 경조사 | C34: 경조비 | D34: 60000 | E34: 720000 | F34: =SUMIF('가계부 내역'!$K:$K,C34,'가계부 내역'!$G:$G) | G34: =E34+F34 | H34: =D34*$B$3+F34 | I34: 실적 117K, 보수적
C35: 3층: 프로젝트 지출 소계 | D35: =SUM(D23:D34) | E35: =SUM(E23:E34) | F35: =SUM(F23:F34) | G35: =SUM(G23:G34) | H35: =SUM(H23:H34)
A36: 비정기 | B36: 건강 | C36: 의료/건강 | D36: 120000 | E36: 1440000 | F36: =SUMIF('가계부 내역'!$K:$K,C36,'가계부 내역'!$G:$G) | G36: =E36+F36 | H36: =D36*$B$3+F36 | I36: 병원 실적 231K, 변동대비
A37: 비정기 | B37: 운영 | C37: 자동차 유지(연간) | D37: 150000 | E37: 1800000 | F37: =SUMIF('가계부 내역'!$K:$K,C37,'가계부 내역'!$G:$G) | G37: =E37+F37 | H37: =D37*$B$3+F37 | I37: 보험갱신/정비/수리
A38: 비정기 | B38: 여행 | C38: 여행 | D38: 200000 | E38: 2400000 | F38: =SUMIF('가계부 내역'!$K:$K,C38,'가계부 내역'!$G:$G) | G38: =E38+F38 | H38: =D38*$B$3+F38 | I38: 여수+일본+속초 등
A39: 비정기 | B39: 관계 | C39: 대형선물 | D39: 100000 | E39: 1200000 | F39: =SUMIF('가계부 내역'!$K:$K,C39,'가계부 내역'!$G:$G) | G39: =E39+F39 | H39: =D39*$B$3+F39 | I39: 비정기 대형 선물
A40: 비정기 | B40: 효도 | C40: 효도 이벤트 | D40: 100000 | E40: 1200000 | F40: =SUMIF('가계부 내역'!$K:$K,C40,'가계부 내역'!$G:$G) | G40: =E40+F40 | H40: =D40*$B$3+F40 | I40: 어머니 여행/큰선물
A41: 비정기 | B41: 생활 | C41: 패션/쇼핑 | D41: 80000 | E41: 960000 | F41: =SUMIF('가계부 내역'!$K:$K,C41,'가계부 내역'!$G:$G) | G41: =E41+F41 | H41: =D41*$B$3+F41 | I41: 실적 219K→절감
...
